Workbook

Sheet ASP-301-1
A1: PS AS
E4: Modul 1
C6: Spannungsversorgung
E12: Modul 13
C14: Spannungsversorgung
E20: Modul 2 | J20: IP:
C21: RAV-205 | J21: Version:
C22: AutomationServer
C23: 10.241.32.115 | J23: User: admin
C24: 255.255.252.0 | J24: Passwort: Admin123!
F27: ='ASP-301-1_DP'!C1 -> M3 RTD-DI-16 | M27: =F27 -> M3 RTD-DI-16
B28: 01 | C28: ='ASP-301-1_DP'!D2 -> RAV205 - Istwert Schaltschrank | I28: 09 | J28: ='ASP-301-1_DP'!D10 -> D.-212 - Istwert Ausblastemperatur
B29: 02 | C29: ='ASP-301-1_DP'!D3 -> D.-207 - Istwert Ausblastemperatur | I29: 10 | J29: ='ASP-301-1_DP'!D11 -> D.-218 - Istwert Ausblastemperatur
B30: 03 | C30: ='ASP-301-1_DP'!D4 -> D.-207 - Istwert Ausblastemperatur | I30: 11 | J30: ='ASP-301-1_DP'!D12 -> D.-213 - Istwert Ausblastemperatur
B31: 04 | C31: ='ASP-301-1_DP'!D5 -> D.-207 - Istwert Ausblastemperatur | I31: 12 | J31: ='ASP-301-1_DP'!D13 -> D.-217 - Istwert Ausblastemperatur
B32: 05 | C32: ='ASP-301-1_DP'!D6 -> D.-207 - Istwert Ausblastemperatur | I32: 13 | J32: ='ASP-301-1_DP'!D14 -> D.-220 - Istwert Ausblastemperatur
B33: 06 | C33: ='ASP-301-1_DP'!D7 -> D.-210 - Istwert Ausblastemperatur | I33: 14 | J33: ='ASP-301-1_DP'!D15 -> D.-221 - Istwert Ausblastemperatur
B34: 07 | C34: ='ASP-301-1_DP'!D8 -> D.-211 - Istwert Ausblastemperatur | I34: 15 | J34: ='ASP-301-1_DP'!D16 -> D.-227 - Istwert Ausblastemperatur
B35: 08 | C35: ='ASP-301-1_DP'!D9 -> D.-211 - Istwert Ausblastemperatur | I35: 16 | J35: ='ASP-301-1_DP'!D17 -> D.-261 - Istwert Ausblastemperatur
F38: ='ASP-301-1_DP'!C18 -> M4 RTD-DI-16 | M38: =F38 -> M4 RTD-DI-16
B39: 01 | C39: ='ASP-301-1_DP'!D19 -> 0 | I39: 09 | J39: ='ASP-301-1_DP'!D27 -> 0
B40: 02 | C40: ='ASP-301-1_DP'!D20 -> D.-275 - Istwert Ausblastemperatur | I40: 10 | J40: ='ASP-301-1_DP'!D28 -> 0
B41: 03 | C41: ='ASP-301-1_DP'!D21 -> D.-288 - Istwert Ausblastemperatur | I41: 11 | J41: ='ASP-301-1_DP'!D29 -> 0
B42: 04 | C42: ='ASP-301-1_DP'!D22 -> 0 | I42: 12 | J42: ='ASP-301-1_DP'!D30 -> 0
B43: 05 | C43: ='ASP-301-1_DP'!D23 -> 0 | I43: 13 | J43: ='ASP-301-1_DP'!D31 -> 0
B44: 06 | C44: ='ASP-301-1_DP'!D24 -> 0 | I44: 14 | J44: ='ASP-301-1_DP'!D32 -> 0
B45: 07 | C45: ='ASP-301-1_DP'!D25 -> 0 | I45: 15 | J45: ='ASP-301-1_DP'!D33 -> 0
B46: 08 | C46: ='ASP-301-1_DP'!D26 -> 0 | I46: 16 | J46: ='ASP-301-1_DP'!D34 -> 0
F49: ='ASP-301-1_DP'!C35 -> M5 UI-16 | M49: =F49 -> M5 UI-16
B50: 01 | C50: ='ASP-301-1_DP'!D36 -> D.-211 - Istwert FCU Heizventil | I50: 09 | J50: ='ASP-301-1_DP'!D44 -> D.-275 - Istwert FCU Heizventil
B51: 02 | C51: ='ASP-301-1_DP'!D37 -> D.-211 - Istwert FCU Heizventil | I51: 10 | J51: ='ASP-301-1_DP'!D45 -> D.-288 - Istwert FCU Heizventil
B52: 03 | C52: ='ASP-301-1_DP'!D38 -> D.-212 - Istwert FCU Heizventil | I52: 11 | J52: ='ASP-301-1_DP'!D46 -> D.-210 - Istwert FCU Kälteventil
B53: 04 | C53: ='ASP-301-1_DP'!D39 -> D.-218 - Istwert FCU Heizventil | I53: 12 | J53: ='ASP-301-1_DP'!D47 -> D.-212 - Istwert FCU Kälteventil
B54: 05 | C54: ='ASP-301-1_DP'!D40 -> 0 | I54: 13 | J54: ='ASP-301-1_DP'!D48 -> D.-218 - Istwert FCU Kälteventil
B55: 06 | C55: ='ASP-301-1_DP'!D41 -> D.-220 - Istwert FCU Heizventil | I55: 14 | J55: ='ASP-301-1_DP'!D49 -> D.-213 - Istwert FCU Kälteventil
B56: 07 | C56: ='ASP-301-1_DP'!D42 -> D.-221 - Istwert FCU Heizventil | I56: 15 | J56: ='ASP-301-1_DP'!D50 -> D.-220 - Istwert FCU Kälteventil
B57: 08 | C57: ='ASP-301-1_DP'!D43 -> D.-227 - Istwert FCU Heizventil | I57: 16 | J57: ='ASP-301-1_DP'!D51 -> D.-221 - Istwert FCU Kälteventil
F60: ='ASP-301-1_DP'!C52 -> M6 UI-16 | M60: =F60 -> M6 UI-16
B61: 01 | C61: ='ASP-301-1_DP'!D53 -> D.-227 - Istwert FCU Kälteventil | I61: 09 | J61: ='ASP-301-1_DP'!D61 -> D.-207 - Istwert HZG/KLG Ventil
B62: 02 | C62: ='ASP-301-1_DP'!D54 -> D.-261 - Istwert FCU Kälteventil | I62: 10 | J62: ='ASP-301-1_DP'!D62 -> D.-217 - Istwert FCU Ventil
...

Sheet ASP-301-1_DP
B1: RTD-DI-16 | C1: M3 RTD-DI-16 | D1: RTD-DI-16 | E1: 3 | AI1: Keine
B2: 2-Kabel RTD Temperatureingang | C2: RAV-205.RAV205.TRU001_MW | D2: RAV205 - Istwert Schaltschrank | F2: In1 | G2: Modicon 1 - M172 - AI1 | S2: 0,00 Δ°C | T2: Pt1000 | V2: 0,00 ohm | W2: TRUE | X2: 0,00 Δ°C | Y2: 25,51 °C | AG2: F2-104 | AI2: Keine
B3: 2-Kabel RTD Temperatureingang | C3: RAV-205.RAUD07.TZU001_MW | D3: D.-207 - Istwert Ausblastemperatur | F3: In2 | G3: Modicon 1 - M172 - AI2 | S3: 0,00 Δ°C | T3: Pt1000 | V3: 0,00 ohm | W3: TRUE | X3: 0,00 Δ°C | Y3: 29,92 °C | AG3: F2-107 | AI3: Keine
B4: 2-Kabel RTD Temperatureingang | C4: RAV-205.RAUD07.TZU002_MW | D4: D.-207 - Istwert Ausblastemperatur | F4: In3 | G4: Modicon 1 - M172 - AI3 | S4: 0,00 Δ°C | T4: Pt1000 | V4: 0,00 ohm | W4: TRUE | X4: 0,00 Δ°C | Y4: 26,46 °C | AG4: F2-110 | AI4: Keine
B5: 2-Kabel RTD Temperatureingang | C5: RAV-205.RAUD07.TZU003_MW | D5: D.-207 - Istwert Ausblastemperatur | F5: In4 | G5: Modicon 1 - M172 - AI4 | S5: 0,00 Δ°C | T5: Pt1000 | V5: 0,00 ohm | W5: TRUE | X5: 0,00 Δ°C | Y5: 27,21 °C | AG5: F2-113 | AI5: Keine
B6: 2-Kabel RTD Temperatureingang | C6: RAV-205.RAUD07.TZU004_MW | D6: D.-207 - Istwert Ausblastemperatur | F6: In5 | G6: Modicon 1 - M172 - AI5 | S6: 0,00 Δ°C | T6: Pt1000 | V6: 0,00 ohm | W6: TRUE | X6: 0,00 Δ°C | Y6: 27,95 °C | AG6: F2-116 | AI6: Keine
B7: 2-Kabel RTD Temperatureingang | C7: RAV-205.RAUD10.TZU001_MW | D7: D.-210 - Istwert Ausblastemperatur | F7: In6 | G7: Modicon 2 - M172 - AI1 | S7: 0,00 Δ°C | T7: Pt1000 | V7: 0,00 ohm | W7: TRUE | X7: 0,00 Δ°C | Y7: 17,90 °C | AG7: F2-123 | AI7: Keine
B8: 2-Kabel RTD Temperatureingang | C8: RAV-205.RAUD11.TZU001_MW | D8: D.-211 - Istwert Ausblastemperatur | F8: In7 | G8: Modicon 2 - M172 - AI2 | S8: 0,00 Δ°C | T8: Pt1000 | V8: 0,00 ohm | W8: TRUE | X8: 0,00 Δ°C | Y8: 27,54 °C | AG8: F2-127 | AI8: Keine
B9: 2-Kabel RTD Temperatureingang | C9: RAV-205.RAUD11.TZU002_MW | D9: D.-211 - Istwert Ausblastemperatur | F9: In8 | G9: Modicon 2 - M172 - AI3 | S9: 0,00 Δ°C | T9: Pt1000 | V9: 0,00 ohm | W9: TRUE | X9: 0,00 Δ°C | Y9: 150,00 °C | AG9: F2-129 | AI9: Keine
B10: 2-Kabel RTD Temperatureingang | C10: RAV-205.RAUD12.TZU001_MW | D10: D.-212 - Istwert Ausblastemperatur | F10: In9 | G10: Modicon 2 - M172 - AI4 | S10: 0,00 Δ°C | T10: Pt1000 | V10: 0,00 ohm | W10: TRUE | X10: 0,00 Δ°C | Y10: 30,33 °C | AG10: F2-132 | AI10: Keine
B11: 2-Kabel RTD Temperatureingang | C11: RAV-205.RAUD18.TZU001_MW | D11: D.-218 - Istwert Ausblastemperatur | F11: In10 | G11: Modicon 2 - M172 - AI5 | S11: 0,00 Δ°C | T11: Pt1000 | V11: 0,00 ohm | W11: TRUE | X11: 0,00 Δ°C | Y11: 30,00 °C | AG11: F2-151 | AI11: Keine
B12: 2-Kabel RTD Temperatureingang | C12: RAV-205.RAUD13.TZU001_MW | D12: D.-213 - Istwert Ausblastemperatur | F12: In11 | G12: Modicon 3 - M172 - AI1 | S12: 0,00 Δ°C | T12: Pt1000 | V12: 0,00 ohm | W12: TRUE | X12: 0,00 Δ°C | Y12: 29,92 °C | AG12: F2-137 | AI12: Keine
B13: 2-Kabel RTD Temperatureingang | C13: RAV-205.RAUD17.TZU001_MW | D13: D.-217 - Istwert Ausblastemperatur | F13: In12 | G13: Modicon 3 - M172 - AI2 | S13: 0,00 Δ°C | T13: Pt1000 | V13: 0,00 ohm | W13: TRUE | X13: 0,00 Δ°C | Y13: 30,18 °C | AG13: F2-146 | AI13: Keine
... B17: 2-Kabel RTD Temperatureingang | C17: RAV-205.RAUD61.TZU001_MW | D17: D.-261 - Istwert Ausblastemperatur | F17: In16 | G17: Modicon 6 - M172 - AI1 | S17: 0,00 Δ°C | T17: Pt1000 | V17: 0,00 ohm | W17: TRUE | X17: 0,00 Δ°C | Y17: 19,28 °C | AG17: F3-190 | AI17: Keine
B18: RTD-DI-16 | C18: M4 RTD-DI-16 | D18: RTD-DI-16 | E18: 4 | AI18: Keine
B19: Leerer Eingang | C19: M4 RTD-DI-16_LeerInput_1? | F19: In1 | K19: FALSE | V19: 0 ohm | Y19: 0,00 °C
B20: 2-Kabel RTD Temperatureingang | C20: RAV-205.RAUD75.TZU001_MW | D20: D.-275 - Istwert Ausblastemperatur | F20: In2 | G20: Modicon 7 - M172 - AI1 | S20: 0,00 Δ°C | T20: Pt1000 | V20: 0,00 ohm | W20: TRUE | X20: 0,00 Δ°C | Y20: 16,67 °C | AG20: F3-207 | AI20: Keine
B21: 2-Kabel RTD Temperatureingang | C21: RAV-205.RAUD88.TZU001_MW | D21: D.-288 - Istwert Ausblastemperatur | F21: In3 | G21: Modicon 7 - M172 - AI2 | S21: 0,00 Δ°C | T21: Pt1000 | V21: 0,00 ohm | W21: TRUE | X21: 0,00 Δ°C | Y21: 29,95 °C | AG21: F3-214 | AI21: Keine
B22: Leerer Eingang | C22: M4 RTD-DI-16_LeerInput_4? | F22: In4 | K22: FALSE | V22: 0 ohm | Y22: 0,00 °C
B23: Leerer Eingang | C23: M4 RTD-DI-16_LeerInput_5? | F23: In5 | K23: FALSE | V23: 0 ohm | Y23: 0,00 °C
B24: Leerer Eingang | C24: M4 RTD-DI-16_LeerInput_6? | F24: In6 | K24: FALSE | V24: 0 ohm | Y24: 0,00 °C
B25: Leerer Eingang | C25: M4 RTD-DI-16_LeerInput_7? | F25: In7 | K25: FALSE | V25: 0 ohm | Y25: 0,00 °C
B26: Leerer Eingang | C26: M4 RTD-DI-16_LeerInput_8? | F26: In8 | K26: FALSE | V26: 0 ohm | Y26: 0,00 °C
B27: Leerer Eingang | C27: M4 RTD-DI-16_LeerInput_9? | F27: In9 | K27: FALSE | V27: 0 ohm | Y27: 0,00 °C
B28: Leerer Eingang | C28: M4 RTD-DI-16_LeerInput_10? | F28: In10 | K28: FALSE | V28: 0 ohm | Y28: 0,00 °C
B29: Leerer Eingang | C29: M4 RTD-DI-16_LeerInput_11? | F29: In11 | K29: FALSE | V29: 0 ohm | Y29: 0,00 °C
B30: Leerer Eingang | C30: M4 RTD-DI-16_LeerInput_12? | F30: In12 | K30: FALSE | V30: 0 ohm | Y30: 0,00 °C
B31: Leerer Eingang | C31: M4 RTD-DI-16_LeerInput_13? | F31: In13 | K31: FALSE | V31: 0 ohm | Y31: 0,00 °C
B32: Leerer Eingang | C32: M4 RTD-DI-16_LeerInput_14? | F32: In14 | K32: FALSE | V32: 0 ohm | Y32: 0,00 °C
B33: Leerer Eingang | C33: M4 RTD-DI-16_LeerInput_15? | F33: In15 | K33: FALSE | V33: 0 ohm | Y33: 0,00 °C
B34: Leerer Eingang | C34: M4 RTD-DI-16_LeerInput_16? | F34: In16 | K34: FALSE | V34: 0 ohm | Y34: 0,00 °C
B35: UI-16 | C35: M5 UI-16 | D35: UI-16 | E35: 5 | AI35: Keine
B36: Spannungseingang | C36: RAV-205.RAUD11.VENh01_MW | D36: D.-211 - Istwert FCU Heizventil | F36: In1 | G36: Modicon 2 - EAP1 - UI1 | M36: 2,00 V | N36: 10,00 V | O36: 0 | P36: 1 | S36: 0 | W36: TRUE | X36: 0 | Y36: -0.2469 | AG36: F2-128 | AI36: Keine
B37: Spannungseingang | C37: RAV-205.RAUD11.VENh02_MW | D37: D.-211 - Istwert FCU Heizventil | F37: In2 | G37: Modicon 2 - EAP1 - UI2 | M37: 2,00 V | N37: 10,00 V | O37: 0 | P37: 1 | S37: 0 | W37: TRUE | X37: 0 | Y37: -0.2476 | AG37: F2-130 | AI37: Keine
B38: Spannungseingang | C38: RAV-205.RAUD12.VENh01_MW | D38: D.-212 - Istwert FCU Heizventil | F38: In3 | G38: Modicon 2 - EAP1 - UI4 | M38: 2,00 V | N38: 10,00 V | O38: 0 | P38: 1 | S38: 0 | W38: TRUE | X38: 0 | Y38: 0.0075 | AG38: F2-134 | AI38: Keine
B39: Spannungseingang | C39: RAV-205.RAUD18.VENh01_MW | D39: D.-218 - Istwert FCU Heizventil | F39: In4 | G39: Modicon 2 - M172 - AI7 | M39: 2,00 V | N39: 10,00 V | O39: 0 | P39: 1 | S39: 0 | W39: TRUE | X39: 0 | Y39: 0.342 | AG39: F2-153 | AI39: Keine
B40: Leerer Eingang | C40: M5 UI-16_LeerInput_5? | F40: In5 | K40: FALSE | V40: 0 ohm | Y40: 0,00 °C
B41: Spannungseingang | C41: RAV-205.RAUD20.VENh01_MW | D41: D.-220 - Istwert FCU Heizventil | F41: In6 | G41: Modicon 4 - EAP1 - UI1 | M41: 2,00 V | N41: 10,00 V | O41: 0 | P41: 1 | S41: 0 | W41: TRUE | X41: 0 | Y41: 0.006 | AG41: F2-157 | AI41: Keine
B42: Spannungseingang | C42: RAV-205.RAUD21.VENh01_MW | D42: D.-221 - Istwert FCU Heizventil | F42: In7 | G42: Modicon 4 - EAP1 - UI3 | M42: 2,00 V | N42: 10,00 V | O42: 0 | P42: 1 | S42: 0 | W42: TRUE | X42: 0 | Y42: 0.0045 | AG42: F2-162 | AI42: Keine
B43: Spannungseingang | C43: RAV-205.RAUD27.VENh01_MW | D43: D.-227 - Istwert FCU Heizventil | F43: In8 | G43: Modicon 5 - EAP1 - UI1 | M43: 2,00 V | N43: 10,00 V | O43: 0 | P43: 1 | S43: 0 | W43: TRUE | X43: 0 | Y43: 0.0049 | AG43: F3-174 | AI43: Keine
...

Sheet ASP0303_DP (2)
B1: DO-FA-12 | C1: M3 253K2 | D1: M3 253K2 - DO-FA-12 | E1: 3 | AI1: Keine
B2: Digitalausgang | C2: ELT303.ASV010_QUT_SB | D2: ELT303 - Schaltbefehl Fernresettaster | F2: Out1 | G2: ASP0303s_Entsperren_SB | H2: FALSE | Y2: Aus | Z2: Aus | AA2: Aus | AG2: =ASP0303s&EFS+F3/ASP0303s/205.4 | AI2: Keine
B3: Digitalausgang | C3: ELT303.ASV010_QUT_SBSSM_LED_SB | D3: ELT303 - Schaltbefehl Summenstörung | F3: Out2 | G3: ASP0303s_SSM_LED_SB | H3: FALSE | Y3: Aus | Z3: Aus | AA3: Aus | AG3: =ASP0303s&EFS+F3/ASP0303s/205.7 | AI3: Keine
B4: Digitalausgang | C4: BMA001.BMZ021_SB | D4: BMA001 - Schaltbefehl BMZ021 | F4: Out3 | G4: ASP0303s_BMA_FUB021_SB | H4: FALSE | Y4: Aus | Z4: Aus | AA4: Aus | AG4: =ASP0303s&EFS+F3/ASP0303s/202.1 | AI4: Keine
B5: Digitalausgang | C5: BMA001.BMZ034_SB | D5: BMA001 - Schaltbefehl BMZ034 | F5: Out4 | G5: ASP0303s_BMA_FUB034_SB | H5: FALSE | Y5: Aus | Z5: Aus | AA5: Aus | AG5: =ASP0303s&EFS+F3/ASP0303s/202.2 | AI5: Keine
B6: Digitalausgang | C6: BMA001.BMZ035_SB | D6: BMA001 - Schaltbefehl BMZ035 | F6: Out5 | G6: ASP0303s_BMA_FUB035_SB | H6: FALSE | Y6: Aus | Z6: Aus | AA6: Aus | AG6: =ASP0303s&EFS+F3/ASP0303s/202.4 | AI6: Keine
B7: Digitalausgang | C7: BMA001.BMZ046_SB | D7: BMA001 - Schaltbefehl BMZ046 | F7: Out6 | G7: ASP0303s_BMA_FUB046_SB | H7: FALSE | Y7: Aus | Z7: Aus | AA7: Aus | AG7: =ASP0303s&EFS+F3/ASP0303s/202.5 | AI7: Keine
B8: Digitalausgang | C8: BMA001.BMZ047_SB | D8: BMA001 - Schaltbefehl BMZ047 | F8: Out7 | G8: ASP0303s_BMA_FUB047_SB | H8: FALSE | Y8: Aus | Z8: Aus | AA8: Aus | AG8: =ASP0303s&EFS+F3/ASP0303s/202.6 | AI8: Keine
B9: Digitalausgang | C9: RLT007.BFS001_AUTO_SB | D9: RLT007 - Schaltbefehl Entrauchung Auto | F9: Out8 | G9: ASP0303s_RLT007_AUTO_SB | H9: FALSE | Y9: Ein | Z9: Ein | AA9: Aus | AG9: =ASP0303s&EFS+F3/ASP0303s/203.1 | AI9: Keine
B10: Digitalausgang | C10: RLT007.BFS001_AUS_SB | D10: RLT007 - Schaltbefehl Entrauchung AUS | F10: Out9 | G10: ASP0303s_RLT007_AUS_SB | H10: FALSE | Y10: Aus | Z10: Aus | AA10: Aus | AG10: =ASP0303s&EFS+F3/ASP0303s/203.2 | AI10: Keine
B11: Digitalausgang | C11: RLT007.BFS001_EIN_SB | D11: RLT007 - Schaltbefehl Entrauchung EIN | F11: Out10 | G11: ASP0303s_RLT007_EIN_SB | H11: FALSE | Y11: Aus | Z11: Aus | AA11: Aus | AG11: =ASP0303s&EFS+F3/ASP0303s/203.3 | AI11: Keine
B12: Digitalausgang | C12: RLT015.BFS001_AUTO_SB | D12: RLT015 - Schaltbefehl Entrauchung Auto | F12: Out11 | G12: ASP0303s_RLT015_AUTO_SB | H12: FALSE | Y12: Aus | Z12: Aus | AA12: Aus | AG12: RBA01.E03.A.319.F=ASP0303s.RLT015.BFS001 | AI12: Keine
B13: Digitalausgang | C13: RLT015.BFS001_AUS_SB | D13: RLT015 - Schaltbefehl Entrauchung AUS | F13: Out12 | G13: ASP0303s_RLT015_AUS_SB | H13: FALSE | Y13: Aus | Z13: Aus | AA13: Aus | AG13: RBA01.E03.A.319.F=ASP0303s.RLT015.BFS001 | AI13: Keine
B14: DO-FA-12 | C14: M4 253K3 | D14: M4 253K3 - DO-FA-12 | E14: 4 | AI14: Keine
B15: Digitalausgang | C15: RLT015.BFS001_EIN_SB | D15: RLT015 - Schaltbefehl Entrauchung EIN | F15: Out1 | G15: ASP0303s_RLT015_EIN_SB | H15: FALSE | Y15: Aus | Z15: Aus | AA15: Aus | AG15: RBA01.E03.A.319.F=ASP0303s.RLT015.BFS001 | AI15: Keine
B16: Digitalausgang | C16: RLT017.BFS001_AUTO_SB | D16: RLT017 - Schaltbefehl Entrauchung Auto | F16: Out2 | G16: ASP0303s_RLT017_AUTO_SB | H16: FALSE | Y16: Aus | Z16: Aus | AA16: Aus | AG16: RBA01.E03.A.319.F=ASP0303s.RLT017.BFS001 | AI16: Keine
B17: Digitalausgang | C17: RLT017.BFS001_AUS_SB | D17: RLT017 - Schaltbefehl Entrauchung AUS | F17: Out3 | G17: ASP0303s_RLT017_AUS_SB | H17: FALSE | Y17: Aus | Z17: Aus | AA17: Aus | AG17: RBA01.E03.A.319.F=ASP0303s.RLT017.BFS001 | AI17: Keine
B18: Digitalausgang | C18: RLT017.BFS001_EIN_SB | D18: RLT017 - Schaltbefehl Entrauchung EIN | F18: Out4 | G18: ASP0303s_RLT017_EIN_SB | H18: FALSE | Y18: Aus | Z18: Aus | AA18: Aus | AG18: RBA01.E03.A.319.F=ASP0303s.RLT017.BFS001 | AI18: Keine
B19: Digitalausgang | C19: RLT007.ZUV001_SB | D19: RLT007 - Schaltbefehl Zuluftventilator | F19: Out5 | G19: ASP-303.RLT17.ZUV001_SB | H19: FALSE | Y19: Ein | Z19: Ein | AA19: Aus | AG19: RBA01.E03.A.319.F=ASP0303s.RLT007.ZUV001 | AH19: geprüft Michael/Kai 29.07.24 | AI19: Keine
B20: Digitalausgang | C20: RLT007.ABV101_SB | D20: RLT007 - Schaltbefehl Abluftventilator | F20: Out6 | G20: ASP-303.RLT17.ABV101_SB | H20: FALSE | Y20: Ein | Z20: Ein | AA20: Aus | AG20: RBA01.E03.A.319.F=ASP0303s.RLT007.ABV101 | AH20: geprüft Michael/Kai 29.07.24 | AI20: Keine
B21: Digitalausgang | C21: RLT007.PPE001_SB | D21: RLT007 - Schaltbefehl Pumpe WRG KVS | F21: Out7 | G21: ASP-303.RLT22A.PPE001_SB | H21: FALSE | Y21: Aus | Z21: Aus | AA21: Aus | AG21: RBA01.E03.A.319.F=ASP0303s.RLT007.KVS001 | AI21: Keine
B22: Digitalausgang | C22: RLT007.LKL001_SB | D22: RLT007 - Schaltbefehl Klappe Aussenluft | F22: Out8 | G22: ASP-303.RLT22A.LKL001_SB | H22: FALSE | Y22: Ein | Z22: Ein | AA22: Aus | AG22: RBA01.E03.A.319.F=ASP0303s.RLT007.LKL001 | AI22: Keine
B23: Digitalausgang | C23: RLT007.LKL101_SB | D23: RLT007 - Schaltbefehl Klappe Fortluft | F23: Out9 | G23: ASP-303.RLT22A.LKL002_SB | H23: FALSE | Y23: Ein | Z23: Ein | AA23: Aus | AG23: RBA01.E03.A.319.F=ASP0303s.RLT007.LKL101 | AI23: Keine
B24: Digitalausgang | C24: RLT015.ZUV001_SB | D24: RLT015 - Schaltbefehl Zuluftventilator | F24: Out10 | G24: RLT015_ZUL_FAN_SB | H24: FALSE | Y24: Aus | Z24: Aus | AA24: Aus | AG24: RBA01.E03.A.319.F=ASP0303s.RLT015.ZUV001 | AI24: Keine
B25: Digitalausgang | C25: RLT015.ABV101_SB | D25: RLT015 - Schaltbefehl Abluftventilator | F25: Out11 | G25: RLT015_ABL_FAN_SB | H25: FALSE | Y25: Aus | Z25: Aus | AA25: Aus | AG25: RBA01.E03.A.319.F=ASP0303s.RLT015.ABV101 | AI25: Keine
B26: Digitalausgang | C26: RLT015.LKL102_SB | D26: RLT015 - Schaltbefehl Klappe Abluft | F26: Out12 | G26: RLT015_ABL_KLP_SB | H26: FALSE | Y26: Aus | Z26: Aus | AA26: Aus | AG26: RBA01.E03.A.319.F=ASP0303s.RLT015.LKL102 | AH26: geprüft Michael/Kai 29.07.24 | AI26: Keine
B27: DO-FC-8 | C27: M5 253K4 | D27: M5 253K4 - DO-FC-8 | E27: 5 | AI27: Keine
B28: Digitalausgang | C28: RLT015.LKL001_SB | D28: RLT015 - Schaltbefehl Klappe Aussenluft | F28: Out1 | G28: RLT015_AUL_KLP_SB | H28: FALSE | Y28: Aus | Z28: Aus | AA28: Aus | AG28: RBA01.E03.A.319.F=ASP0303s.RLT015.LKL001 | AH28: geprüft Michael/Kai 29.07.24 | AI28: Keine
B29: Digitalausgang | C29: RLT015.LKL101_SB | D29: RLT015 - Schaltbefehl Klappe Abluft | F29: Out2 | G29: RLT015_FOL_KLP_SB | H29: FALSE | Y29: Aus | Z29: Aus | AA29: Aus | AG29: RBA01.E03.A.319.F=ASP0303s.RLT015.LKL101 | AH29: geprüft Michael/Kai 29.07.24 | AI29: Keine
B30: Leerer Ausgang | C30: M5 253K4_Leer Output_3? | F30: Out3 | Y30: 0,00 V | Z30: 0,00 V
B31: Leerer Ausgang | C31: M5 253K4_Leer Output_4? | F31: Out4 | Y31: 0,00 V | Z31: 0,00 V
B32: Leerer Ausgang | C32: M5 253K4_Leer Output_5? | F32: Out5 | Y32: 0,00 V | Z32: 0,00 V
B33: Leerer Ausgang | C33: M5 253K4_Leer Output_6? | F33: Out6 | Y33: 0,00 V | Z33: 0,00 V
B34: Leerer Ausgang | C34: M5 253K4_Leer Output_7? | F34: Out7 | Y34: 0,00 V | Z34: 0,00 V
B35: Leerer Ausgang | C35: M5 253K4_Leer Output_8? | F35: Out8 | Y35: 0,00 V | Z35: 0,00 V
B36: AO-V-8 | C36: M6 253K5 | D36: M6 253K5 - AO-V-8 | E36: 6 | AI36: Keine
B37: Spannungsausgang | C37: RLT007.ZUV001_YB | D37: RLT007 - Stellsignal Zuluftventilator | F37: Out1 | G37: RLT007_ZUL_FAN_YB | M37: 0,00 V | N37: 10,00 V | O37: 0 | P37: 1 | X37: 0 | Y37: 0 | Z37: 0 | AA37: 0 | AG37: RBA01.E03.A.319.F=ASP0303s.RLT007.ZUV001 | AH37: geprüft Michael/Kai 29.07.24 | AI37: Keine
B38: Spannungsausgang | C38: RLT007.ABV101_YB | D38: RLT007 - Stellsignal Abluftventilator | F38: Out2 | G38: RLT007_ABL_FAN_YB | M38: 0,00 V | N38: 10,00 V | O38: 0 | P38: 1 | X38: 0 | Y38: 0 | Z38: 0 | AA38: 0 | AG38: RBA01.E03.A.319.F=ASP0303s.RLT007.ABV101 | AH38: geprüft Michael/Kai 29.07.24 | AI38: Keine
B39: Spannungsausgang | C39: RLT007.PPE001_YB | D39: RLT007 - Stellsignal Pumpe WRG KSV | F39: Out3 | G39: RLT007_PUM_YB | M39: 0,00 V | N39: 10,00 V | O39: 0 | P39: 1 | X39: 0 | Y39: 0 | Z39: 0 | AA39: 0 | AG39: RBA01.E03.A.319.F=ASP0303s.RLT007.KVS001 | AI39: Keine
B40: Spannungsausgang | C40: RLT007.LKL004_YB | D40: RLT007 - Stellsignal WRG Klappe 1 | F40: Out4 | G40: RLT007_WRG_KLP_YB | M40: 0,00 V | N40: 10,00 V | O40: 0 | P40: 1 | X40: 0 | Y40: 1 | Z40: 1 | AA40: 0 | AG40: RBA01.E03.A.319.F=ASP0303s.RLT007.LKL004 | AI40: Keine
...
